Workbook

Sheet Instructions
B2: Step-by-Step Instructions
B4: Step | C4: Details
B5: 1 | C5: Go to the Inputs sheet and fill all highlighted Light Blue cells.
B6: 2 | C6: Enter the Years to Exit and Discount Rate (%) under General Assumptions.
B7: 3 | C7: Enter the projected Revenue at Exit for the Best Case, Base Case, and Worst Case scenarios.
B8: 4 | C8: Enter the expected Revenue Multiple for each scenario based on industry benchmarks and market conditions (Go through the Revenue multiple benchmarks table below for reference)
B9: 5 | C9: Assign a probability (%) to each scenario. Ensure the total probability equals 100% (Go through the Probability allocation table below for reference)
B10: 6 | C10: Review the automatically calculated results in the Valuation sheet.
B11: 7 | C11: Refer to the Industry Revenue Multiple Guide below if you need assistance selecting a revenue multiple.
B14: What Each Input Means
B16: Input | C16: Description
B17: Years to Exit | C17: Number of years until the expected exit event, acquisition, or liquidity event.
B18: Discount Rate (%) | C18: Annual rate used to adjust future values for risk and time value of money.
B19: Revenue at Exit | C19: Expected annual revenue of the company at the time of exit.
B20: Revenue Multiple | C20: Revenue valuation multiple applied to estimate the company's exit value.
B21: Scenario Probability (%) | C21: Likelihood of each scenario occurring. Total probabilities must equal 100%.
B24: Important Guidelines
B26: Guideline | C26: Description
B27: Edit Light Blue Cells Only | C27: Light Blue cells are manual input cells. Other cells contain formulas and should not be modified.
B28: Use Consistent Units | C28: Use the same monetary unit throughout the template (e.g., INR Lakhs, INR Crores, USD Millions).
B29: Probability Check | C29: Total probability across all scenarios must equal 100%.
B30: Use Realistic Assumptions | C30: Revenue projections, multiples, and probabilities should be based on reasonable expectations.
B31: Review Results Carefully | C31: The final valuation is only as reliable as the assumptions entered.
B34: Industry Revenue Multiple Reference Guide
B36: Industry | C36: Typical Revenue Multiple Range
B37: SaaS / Software | C37: 3x – 8x
B38: AI / DeepTech | C38: 4x – 10x
B39: FinTech | C39: 3x – 8x
B40: Marketplace Platforms | C40: 2x – 6x
B41: EdTech | C41: 2x – 5x
B42: HealthTech | C42: 2x – 6x
B43: D2C / Consumer Brands | C43: 1x – 3x
B44: E-Commerce | C44: 1x – 3x
B45: Food & Beverage | C45: 1x – 3x
B46: Logistics & Supply Chain | C46: 1x – 3x
B47: Manufacturing | C47: 0.5x – 2x
B48: Professional Services | C48: 0.5x – 2x
B50: Suggested Scenario Probability Allocation
B52: Scenario | C52: Typical Probability Range
B53: Best Case | C53: 20% – 30%
...

Sheet Inputs
B2: General Assumptions
B4: General Assumptions | C4: Value
B5: Years to Exit | C5: 5
B6: Discount Rate (%) | C6: 0.15
B9: Scenario Assumptions
B11: Particulars | C11: Best Case | D11: Base Case | E11: Worst Case
B12: Revenue at Exit | C12: 2000000 | D12: 1800000 | E12: 1500000
B13: Revenue Multiple | C13: 6 | D13: 4 | E13: 2
B14: Probability (%) | C14: 0.25 | D14: 0.4 | E14: 0.35

Sheet Valuation
B2: First Chicago Valuation
B4: Particulars | C4: Best Case | D4: Base Case | E4: Worst Case
B5: Revenue at Exit | C5: =Inputs!C12 -> 2000000 | D5: =Inputs!D12 -> 1800000 | E5: =Inputs!E12 -> 1500000
B6: Revenue Multiple | C6: =Inputs!C13 -> 6 | D6: =Inputs!D13 -> 4 | E6: =Inputs!E13 -> 2
B7: Exit Value | C7: =C5*C6 -> 12000000 | D7: =D5*D6 -> 7200000 | E7: =E5*E6 -> 3000000
B8: Present Value Factor | C8: =1/(1+Inputs!C6)^Inputs!C5 -> 0.49717674 | D8: =C8 -> 0.49717674 | E8: =D8 -> 0.49717674
B9: Present Value | C9: =C7*C8 -> 5966120.8 | D9: =D7*D8 -> 3579672.5 | E9: =E7*E8 -> 1491530.2
B10: Probability (%) | C10: =Inputs!C14 -> 0.25 | D10: =Inputs!D14 -> 0.4 | E10: =Inputs!E14 -> 0.35
B11: Probability Weighted Value | C11: =C9*C10 -> 1491530.2 | D11: =D9*D10 -> 1431869 | E11: =E9*E10 -> 522035.57
B14: Final Valuation | C14: =SUM(C11:E11) -> 3445434.8
B17: Interpretation:
B18: This valuation represents the probability-weighted present value of the startup based on the Best Case, Base Case, and Worst Case scenarios entered in the Inputs sheet.
